<?xml version="1.0" encoding="UTF-8"?>
<testsuite errors="4" failures="0" name="tests.DayTestCase-20181128010939" skipped="0" tests="4" time="0.443" timestamp="2018-11-28T01:09:39">
	<testcase classname="tests.DayTestCase" name="test_Day_day_tests" time="0.113" timestamp="2018-11-28T01:09:39">
		<error message="get() returned more than one Day -- it returned 2!" type="MultipleObjectsReturned">
<![CDATA[Traceback (most recent call last):
  File "/Users/jessecook/Desktop/GitHub/mysite/home/tests.py", line 48, in test_Day_day_tests
    self.test_anxiety = Day.objects.get(user=self.user.id)
  File "/anaconda3/lib/python3.5/site-packages/django/db/models/manager.py", line 82, in manager_method
    return getattr(self.get_queryset(), name)(*args, **kwargs)
  File "/anaconda3/lib/python3.5/site-packages/django/db/models/query.py", line 403, in get
    (self.model._meta.object_name, num)
home.models.Day.MultipleObjectsReturned: get() returned more than one Day -- it returned 2!
]]>		</error>
	</testcase>
	<testcase classname="tests.DayTestCase" name="test_Day_log_tests" time="0.112" timestamp="2018-11-28T01:09:39">
		<error message="get() returned more than one Day -- it returned 2!" type="MultipleObjectsReturned">
<![CDATA[Traceback (most recent call last):
  File "/Users/jessecook/Desktop/GitHub/mysite/home/tests.py", line 58, in test_Day_log_tests
    self.test_anxiety = Day.objects.get(user=self.user.id)
  File "/anaconda3/lib/python3.5/site-packages/django/db/models/manager.py", line 82, in manager_method
    return getattr(self.get_queryset(), name)(*args, **kwargs)
  File "/anaconda3/lib/python3.5/site-packages/django/db/models/query.py", line 403, in get
    (self.model._meta.object_name, num)
home.models.Day.MultipleObjectsReturned: get() returned more than one Day -- it returned 2!
]]>		</error>
	</testcase>
	<testcase classname="tests.DayTestCase" name="test_Day_rating_tests" time="0.109" timestamp="2018-11-28T01:09:39">
		<error message="get() returned more than one Day -- it returned 2!" type="MultipleObjectsReturned">
<![CDATA[Traceback (most recent call last):
  File "/Users/jessecook/Desktop/GitHub/mysite/home/tests.py", line 22, in test_Day_rating_tests
    self.test_anxiety = Day.objects.get(user=self.user.id)
  File "/anaconda3/lib/python3.5/site-packages/django/db/models/manager.py", line 82, in manager_method
    return getattr(self.get_queryset(), name)(*args, **kwargs)
  File "/anaconda3/lib/python3.5/site-packages/django/db/models/query.py", line 403, in get
    (self.model._meta.object_name, num)
home.models.Day.MultipleObjectsReturned: get() returned more than one Day -- it returned 2!
]]>		</error>
	</testcase>
	<testcase classname="tests.DayTestCase" name="test_Day_user_tests" time="0.108" timestamp="2018-11-28T01:09:39">
		<error message="get() returned more than one Day -- it returned 2!" type="MultipleObjectsReturned">
<![CDATA[Traceback (most recent call last):
  File "/Users/jessecook/Desktop/GitHub/mysite/home/tests.py", line 34, in test_Day_user_tests
    self.test_anxiety = Day.objects.get(user=self.user.id)
  File "/anaconda3/lib/python3.5/site-packages/django/db/models/manager.py", line 82, in manager_method
    return getattr(self.get_queryset(), name)(*args, **kwargs)
  File "/anaconda3/lib/python3.5/site-packages/django/db/models/query.py", line 403, in get
    (self.model._meta.object_name, num)
home.models.Day.MultipleObjectsReturned: get() returned more than one Day -- it returned 2!
]]>		</error>
	</testcase>
	<system-out>
<![CDATA[







]]>	</system-out>
	<system-err>
<![CDATA[]]>	</system-err>
</testsuite>
