<?xml version="1.0" encoding="UTF-8"?>
<testsuite errors="1" failures="0" name="tests.DayTestCase-20181128011312" skipped="0" tests="4" time="0.435" timestamp="2018-11-28T01:13:13">
	<testcase classname="tests.DayTestCase" name="test_Day_day_tests" time="0.111" timestamp="2018-11-28T01:13:13"/>
	<testcase classname="tests.DayTestCase" name="test_Day_rating_tests" time="0.109" timestamp="2018-11-28T01:13:13"/>
	<testcase classname="tests.DayTestCase" name="test_Day_user_tests" time="0.109" timestamp="2018-11-28T01:13:13"/>
	<testcase classname="tests.DayTestCase" name="test_Day_log_tests" time="0.106" timestamp="2018-11-28T01:13:13">
		<error message="get() returned more than one Day -- it returned 2!" type="MultipleObjectsReturned">
<![CDATA[Traceback (most recent call last):
  File "/Users/jessecook/Desktop/GitHub/mysite/home/tests.py", line 58, in test_Day_log_tests
    self.test_anxiety = Day.objects.get(user=self.user.id)
  File "/anaconda3/lib/python3.5/site-packages/django/db/models/manager.py", line 82, in manager_method
    return getattr(self.get_queryset(), name)(*args, **kwargs)
  File "/anaconda3/lib/python3.5/site-packages/django/db/models/query.py", line 403, in get
    (self.model._meta.object_name, num)
home.models.Day.MultipleObjectsReturned: get() returned more than one Day -- it returned 2!
]]>		</error>
	</testcase>
	<system-out>
<![CDATA[

test_anxiety.day:  1999-12-31
test_depression.day:  2018-11-28


test_anxiety.rating:  50.0
test_depression.rating:  60.0


The user.id of test_anxiety:  5
The user.id of test_depression:  5
The user of test_anxiety:  test
The user of test_depression:  test


]]>	</system-out>
	<system-err>
<![CDATA[]]>	</system-err>
</testsuite>
